2018-06-29 10:10:09,922|WARNING|base_events.py:1308|_run_once|Executing <Task pending coro=<RedisConnection._read_data() running at /usr/local/lib/python3.5/dist-packages/aioredis/connection.py:132> wait_for=<Future pending cb=[Task._wakeup()] created at /usr/lib/python3.5/asyncio/base_events.py:252> cb=[Future.set_result()] created at /usr/local/lib/python3.5/dist-packages/aioredis/connection.py:111> took 1.033 seconds
2018-06-29 10:30:48,936|WARNING|base_events.py:1308|_run_once|Executing <Task pending coro=<RedisConnection._read_data() running at /usr/local/lib/python3.5/dist-packages/aioredis/connection.py:132> wait_for=<Future pending cb=[Task._wakeup()] created at /usr/lib/python3.5/asyncio/base_events.py:252> cb=[Future.set_result()] created at /usr/local/lib/python3.5/dist-packages/aioredis/connection.py:111> took 0.125 seconds
2018-06-29 10:46:10,297|WARNING|base_events.py:1308|_run_once|Executing <Task pending coro=<classFIFOMgr.updateFifoChannel() running at /home/python/Desktop/company_project/server/lib/fifoMgr.py:103> wait_for=<Future pending cb=[Task._wakeup()] created at /usr/lib/python3.5/asyncio/base_events.py:252> created at /home/python/Desktop/company_project/server/connect/connect_svr.py:319> took 0.208 seconds
2018-06-29 10:46:10,724|WARNING|base_events.py:1308|_run_once|Executing <Task pending coro=<classFIFOMgr.updateFifoChannel() running at /home/python/Desktop/company_project/server/lib/fifoMgr.py:103> wait_for=<Future pending cb=[Task._wakeup()] created at /usr/lib/python3.5/asyncio/base_events.py:252> created at /home/python/Desktop/company_project/server/connect/connect_svr.py:319> took 0.109 seconds
2018-06-29 10:49:35,510|WARNING|base_events.py:1308|_run_once|Executing <TimerHandle when=44632.913197909 _set_result_unless_cancelled(<Future finis...events.py:252>, None) at /usr/lib/python3.5/asyncio/futures.py:369 created at /usr/lib/python3.5/asyncio/tasks.py:514> took 0.181 seconds
2018-06-29 10:50:06,180|WARNING|base_events.py:1308|_run_once|Executing <Task pending coro=<classFIFOMgr.updateFifoChannel() running at /home/python/Desktop/company_project/server/lib/fifoMgr.py:103> wait_for=<Future pending cb=[Task._wakeup()] created at /usr/lib/python3.5/asyncio/base_events.py:252> created at /home/python/Desktop/company_project/server/connect/connect_svr.py:319> took 0.138 seconds
2018-06-29 10:51:25,734|WARNING|base_events.py:1308|_run_once|Executing <Handle _SelectorSocketTransport._read_ready() created at /usr/lib/python3.5/asyncio/selector_events.py:232> took 0.112 seconds
2018-06-29 11:32:17,399|WARNING|base_events.py:1308|_run_once|Executing <TimerHandle when=47194.603928008 _set_result_unless_cancelled(<Future finis...events.py:252>, None) at /usr/lib/python3.5/asyncio/futures.py:369 created at /usr/lib/python3.5/asyncio/tasks.py:514> took 0.395 seconds
2018-06-29 11:32:17,939|WARNING|base_events.py:1308|_run_once|Executing <Task pending coro=<classFIFOMgr.updateFifoChannel() running at /home/python/Desktop/company_project/server/lib/fifoMgr.py:117> wait_for=<Future pending cb=[Task._wakeup()] created at /usr/lib/python3.5/asyncio/base_events.py:252> created at /home/python/Desktop/company_project/server/connect/connect_svr.py:319> took 0.321 seconds
2018-06-29 11:54:08,453|WARNING|base_events.py:1308|_run_once|Executing <TimerHandle when=48505.909346401 _set_result_unless_cancelled(<Future finis...events.py:252>, None) at /usr/lib/python3.5/asyncio/futures.py:369 created at /usr/lib/python3.5/asyncio/tasks.py:514> took 0.115 seconds
2018-06-29 13:48:06,220|WARNING|base_events.py:1308|_run_once|Executing <Handle _SelectorSocketTransport._read_ready() created at /usr/lib/python3.5/asyncio/selector_events.py:232> took 0.157 seconds
2018-06-29 13:52:24,524|WARNING|base_events.py:1308|_run_once|Executing <Task pending coro=<classFIFOMgr.updateFifoChannel() running at /home/python/Desktop/company_project/server/lib/fifoMgr.py:117> wait_for=<Future pending cb=[Task._wakeup()] created at /usr/lib/python3.5/asyncio/base_events.py:252> created at /home/python/Desktop/company_project/server/connect/connect_svr.py:319> took 0.103 seconds
2018-06-29 14:06:20,177|WARNING|base_events.py:1308|_run_once|Executing <Task pending coro=<classFIFOMgr.updateFifoChannel() running at /home/python/Desktop/company_project/server/lib/fifoMgr.py:117> wait_for=<Future pending cb=[Task._wakeup()] created at /usr/lib/python3.5/asyncio/base_events.py:252> created at /home/python/Desktop/company_project/server/connect/connect_svr.py:319> took 0.136 seconds
2018-06-29 14:50:56,002|ERROR|fifoMgr.py:121|updateFifoChannel|CancelledError()
2018-06-29 14:50:56,006|ERROR|reciveMgr.py:74|updatePushData|CancelledError()
2018-06-29 14:50:56,013|ERROR|base_events.py:1148|default_exception_handler|Task was destroyed but it is pending!
source_traceback: Object created at (most recent call last):
  File "/home/python/.pycharm_helpers/pydev/pydevd.py", line 1599, in <module>
    globals = debugger.run(setup['file'], None, None, is_module)
  File "/home/python/.pycharm_helpers/pydev/pydevd.py", line 1026, in run
    pydev_imports.execfile(file, globals, locals)  # execute the script
  File "/home/python/.pycharm_helpers/pydev/_pydev_imps/_pydev_execfile.py", line 18, in execfile
    exec(compile(contents+"\n", file, 'exec'), glob, loc)
  File "/home/python/Desktop/company_project/server/connect/connect_svr.py", line 462, in <module>
    g_obj_loop.run_forever()
  File "/usr/lib/python3.5/asyncio/base_events.py", line 345, in run_forever
    self._run_once()
  File "/usr/lib/python3.5/asyncio/base_events.py", line 1304, in _run_once
    handle._run()
  File "/usr/lib/python3.5/asyncio/events.py", line 125, in _run
    self._callback(*self._args)
  File "/usr/lib/python3.5/asyncio/tasks.py", line 299, in _wakeup
    self._step(exc)
  File "/usr/lib/python3.5/asyncio/tasks.py", line 241, in _step
    result = coro.throw(exc)
  File "/home/python/Desktop/company_project/server/lib/reciveMgr.py", line 72, in updatePushData
    yield from self.callFunction(objPushData[0],objPushData[1])
  File "/usr/local/lib/python3.5/dist-packages/aioredis/pool.py", line 310, in __exit__
    self._pool.release(self._conn)
  File "/usr/local/lib/python3.5/dist-packages/aioredis/pool.py", line 218, in release
    async_task(self._wakeup(), loop=self._loop)
task: <Task pending coro=<RedisPool._wakeup() running at /usr/local/lib/python3.5/dist-packages/aioredis/pool.py:263> created at /usr/local/lib/python3.5/dist-packages/aioredis/pool.py:218>
2018-06-29 14:50:56,065|ERROR|base_events.py:1148|default_exception_handler|Task was destroyed but it is pending!
source_traceback: Object created at (most recent call last):
  File "/home/python/.pycharm_helpers/pydev/pydevd.py", line 1599, in <module>
    globals = debugger.run(setup['file'], None, None, is_module)
  File "/home/python/.pycharm_helpers/pydev/pydevd.py", line 1026, in run
    pydev_imports.execfile(file, globals, locals)  # execute the script
  File "/home/python/.pycharm_helpers/pydev/_pydev_imps/_pydev_execfile.py", line 18, in execfile
    exec(compile(contents+"\n", file, 'exec'), glob, loc)
  File "/home/python/Desktop/company_project/server/connect/connect_svr.py", line 455, in <module>
    g_obj_loop.run_forever()
  File "/usr/lib/python3.5/asyncio/base_events.py", line 345, in run_forever
    self._run_once()
  File "/usr/lib/python3.5/asyncio/base_events.py", line 1304, in _run_once
    handle._run()
  File "/usr/lib/python3.5/asyncio/events.py", line 125, in _run
    self._callback(*self._args)
  File "/usr/lib/python3.5/asyncio/tasks.py", line 307, in _wakeup
    self._step()
  File "/usr/lib/python3.5/asyncio/tasks.py", line 239, in _step
    result = coro.send(None)
  File "/home/python/Desktop/company_project/server/connect/connect_svr.py", line 373, in init
    yield from __initUpdate()
  File "/usr/lib/python3.5/asyncio/coroutines.py", line 206, in coro
    res = func(*args, **kw)
  File "/home/python/Desktop/company_project/server/connect/connect_svr.py", line 322, in __initUpdate
    asyncio.ensure_future(reciveMgr.classReciveMgr.getInstance().updatePushData(procVariable.host,procVariable.group_id))
task: <Task pending coro=<classReciveMgr.updatePushData() running at /home/python/Desktop/company_project/server/lib/reciveMgr.py:68> wait_for=<Future pending cb=[Task._wakeup()] created at /usr/lib/python3.5/asyncio/base_events.py:252> cb=[gather.<locals>._done_callback(4)() at /usr/lib/python3.5/asyncio/tasks.py:637] created at /home/python/Desktop/company_project/server/connect/connect_svr.py:322>
2018-06-29 15:02:31,248|WARNING|base_events.py:1308|_run_once|Executing <Handle _SelectorSocketTransport._read_ready() created at /usr/lib/python3.5/asyncio/selector_events.py:232> took 0.105 seconds
2018-06-29 15:07:36,704|WARNING|base_events.py:1308|_run_once|Executing <Task pending coro=<RedisConnection._read_data() running at /usr/local/lib/python3.5/dist-packages/aioredis/connection.py:132> wait_for=<Future pending cb=[Task._wakeup()] created at /usr/lib/python3.5/asyncio/base_events.py:252> cb=[Future.set_result()] created at /usr/local/lib/python3.5/dist-packages/aioredis/connection.py:111> took 0.102 seconds
2018-06-29 15:16:27,375|ERROR|fifoMgr.py:121|updateFifoChannel|CancelledError()
2018-06-29 15:16:27,382|ERROR|reciveMgr.py:74|updatePushData|CancelledError()
2018-06-29 15:16:27,396|ERROR|base_events.py:1148|default_exception_handler|Task was destroyed but it is pending!
source_traceback: Object created at (most recent call last):
  File "/home/python/.pycharm_helpers/pydev/pydevd.py", line 1599, in <module>
    globals = debugger.run(setup['file'], None, None, is_module)
  File "/home/python/.pycharm_helpers/pydev/pydevd.py", line 1026, in run
    pydev_imports.execfile(file, globals, locals)  # execute the script
  File "/home/python/.pycharm_helpers/pydev/_pydev_imps/_pydev_execfile.py", line 18, in execfile
    exec(compile(contents+"\n", file, 'exec'), glob, loc)
  File "/home/python/Desktop/company_project/server/connect/connect_svr.py", line 462, in <module>
    g_obj_loop.run_forever()
  File "/usr/lib/python3.5/asyncio/base_events.py", line 345, in run_forever
    self._run_once()
  File "/usr/lib/python3.5/asyncio/base_events.py", line 1304, in _run_once
    handle._run()
  File "/usr/lib/python3.5/asyncio/events.py", line 125, in _run
    self._callback(*self._args)
  File "/usr/lib/python3.5/asyncio/tasks.py", line 299, in _wakeup
    self._step(exc)
  File "/usr/lib/python3.5/asyncio/tasks.py", line 241, in _step
    result = coro.throw(exc)
  File "/home/python/Desktop/company_project/server/lib/reciveMgr.py", line 72, in updatePushData
    yield from self.callFunction(objPushData[0],objPushData[1])
  File "/usr/local/lib/python3.5/dist-packages/aioredis/pool.py", line 310, in __exit__
    self._pool.release(self._conn)
  File "/usr/local/lib/python3.5/dist-packages/aioredis/pool.py", line 218, in release
    async_task(self._wakeup(), loop=self._loop)
task: <Task pending coro=<RedisPool._wakeup() running at /usr/local/lib/python3.5/dist-packages/aioredis/pool.py:263> created at /usr/local/lib/python3.5/dist-packages/aioredis/pool.py:218>
2018-06-29 15:16:27,448|ERROR|base_events.py:1148|default_exception_handler|Task was destroyed but it is pending!
source_traceback: Object created at (most recent call last):
  File "/home/python/.pycharm_helpers/pydev/pydevd.py", line 1599, in <module>
    globals = debugger.run(setup['file'], None, None, is_module)
  File "/home/python/.pycharm_helpers/pydev/pydevd.py", line 1026, in run
    pydev_imports.execfile(file, globals, locals)  # execute the script
  File "/home/python/.pycharm_helpers/pydev/_pydev_imps/_pydev_execfile.py", line 18, in execfile
    exec(compile(contents+"\n", file, 'exec'), glob, loc)
  File "/home/python/Desktop/company_project/server/connect/connect_svr.py", line 455, in <module>
    g_obj_loop.run_forever()
  File "/usr/lib/python3.5/asyncio/base_events.py", line 345, in run_forever
    self._run_once()
  File "/usr/lib/python3.5/asyncio/base_events.py", line 1304, in _run_once
    handle._run()
  File "/usr/lib/python3.5/asyncio/events.py", line 125, in _run
    self._callback(*self._args)
  File "/usr/lib/python3.5/asyncio/tasks.py", line 307, in _wakeup
    self._step()
  File "/usr/lib/python3.5/asyncio/tasks.py", line 239, in _step
    result = coro.send(None)
  File "/home/python/Desktop/company_project/server/connect/connect_svr.py", line 373, in init
    yield from __initUpdate()
  File "/usr/lib/python3.5/asyncio/coroutines.py", line 206, in coro
    res = func(*args, **kw)
  File "/home/python/Desktop/company_project/server/connect/connect_svr.py", line 322, in __initUpdate
    asyncio.ensure_future(reciveMgr.classReciveMgr.getInstance().updatePushData(procVariable.host,procVariable.group_id))
task: <Task pending coro=<classReciveMgr.updatePushData() running at /home/python/Desktop/company_project/server/lib/reciveMgr.py:68> wait_for=<Future pending cb=[Task._wakeup()] created at /usr/lib/python3.5/asyncio/base_events.py:252> cb=[gather.<locals>._done_callback(6)() at /usr/lib/python3.5/asyncio/tasks.py:637] created at /home/python/Desktop/company_project/server/connect/connect_svr.py:322>
2018-06-29 15:59:41,959|WARNING|base_events.py:1308|_run_once|Executing <Task pending coro=<classFIFOMgr.updateFifoChannel() running at /home/python/Desktop/company_project/server/lib/fifoMgr.py:117> wait_for=<Future pending cb=[Task._wakeup()] created at /usr/lib/python3.5/asyncio/base_events.py:252> created at /home/python/Desktop/company_project/server/connect/connect_svr.py:319> took 0.136 seconds
2018-06-29 16:15:31,486|WARNING|base_events.py:1308|_run_once|Executing <TimerHandle when=64188.980739857 _set_result_unless_cancelled(<Future finis...events.py:252>, None) at /usr/lib/python3.5/asyncio/futures.py:369 created at /usr/lib/python3.5/asyncio/tasks.py:514> took 0.110 seconds
2018-06-29 17:49:42,632|WARNING|base_events.py:1308|_run_once|Executing <Task pending coro=<classFIFOMgr.updateFifoChannel() running at /home/python/Desktop/company_project/server/lib/fifoMgr.py:117> wait_for=<Future pending cb=[Task._wakeup()] created at /usr/lib/python3.5/asyncio/base_events.py:252> created at /home/python/Desktop/company_project/server/connect/connect_svr.py:319> took 0.124 seconds
2018-06-29 18:06:43,419|WARNING|base_events.py:1308|_run_once|Executing <Task pending coro=<RedisConnection._read_data() running at /usr/local/lib/python3.5/dist-packages/aioredis/connection.py:132> wait_for=<Future pending cb=[Task._wakeup()] created at /usr/lib/python3.5/asyncio/base_events.py:252> cb=[Future.set_result()] created at /usr/local/lib/python3.5/dist-packages/aioredis/connection.py:111> took 0.181 seconds
2018-06-29 20:26:22,376|WARNING|base_events.py:1308|_run_once|Executing <Task pending coro=<classFIFOMgr.updateFifoChannel() running at /home/python/Desktop/company_project/server/lib/fifoMgr.py:117> wait_for=<Future pending cb=[Task._wakeup()] created at /usr/lib/python3.5/asyncio/base_events.py:252> created at /home/python/Desktop/company_project/server/connect/connect_svr.py:319> took 0.105 seconds
2018-06-29 20:48:54,452|WARNING|base_events.py:1308|_run_once|Executing <Task pending coro=<classFIFOMgr.updateFifoChannel() running at /home/python/Desktop/company_project/server/lib/fifoMgr.py:103> wait_for=<Future pending cb=[Task._wakeup()] created at /usr/lib/python3.5/asyncio/base_events.py:252> created at /home/python/Desktop/company_project/server/connect/connect_svr.py:319> took 0.187 seconds
2018-06-29 20:50:35,530|ERROR|fifoMgr.py:121|updateFifoChannel|CancelledError()
2018-06-29 20:50:35,534|ERROR|reciveMgr.py:74|updatePushData|CancelledError()
2018-06-29 20:50:35,541|ERROR|base_events.py:1148|default_exception_handler|Task was destroyed but it is pending!
source_traceback: Object created at (most recent call last):
  File "/home/python/.pycharm_helpers/pydev/pydevd.py", line 1599, in <module>
    globals = debugger.run(setup['file'], None, None, is_module)
  File "/home/python/.pycharm_helpers/pydev/pydevd.py", line 1026, in run
    pydev_imports.execfile(file, globals, locals)  # execute the script
  File "/home/python/.pycharm_helpers/pydev/_pydev_imps/_pydev_execfile.py", line 18, in execfile
    exec(compile(contents+"\n", file, 'exec'), glob, loc)
  File "/home/python/Desktop/company_project/server/connect/connect_svr.py", line 462, in <module>
    g_obj_loop.run_forever()
  File "/usr/lib/python3.5/asyncio/base_events.py", line 345, in run_forever
    self._run_once()
  File "/usr/lib/python3.5/asyncio/base_events.py", line 1304, in _run_once
    handle._run()
  File "/usr/lib/python3.5/asyncio/events.py", line 125, in _run
    self._callback(*self._args)
  File "/usr/lib/python3.5/asyncio/tasks.py", line 299, in _wakeup
    self._step(exc)
  File "/usr/lib/python3.5/asyncio/tasks.py", line 241, in _step
    result = coro.throw(exc)
  File "/home/python/Desktop/company_project/server/lib/reciveMgr.py", line 72, in updatePushData
    yield from self.callFunction(objPushData[0],objPushData[1])
  File "/usr/local/lib/python3.5/dist-packages/aioredis/pool.py", line 310, in __exit__
    self._pool.release(self._conn)
  File "/usr/local/lib/python3.5/dist-packages/aioredis/pool.py", line 218, in release
    async_task(self._wakeup(), loop=self._loop)
task: <Task pending coro=<RedisPool._wakeup() running at /usr/local/lib/python3.5/dist-packages/aioredis/pool.py:263> created at /usr/local/lib/python3.5/dist-packages/aioredis/pool.py:218>
2018-06-29 20:50:35,812|ERROR|base_events.py:1148|default_exception_handler|Task was destroyed but it is pending!
source_traceback: Object created at (most recent call last):
  File "/home/python/.pycharm_helpers/pydev/pydevd.py", line 1599, in <module>
    globals = debugger.run(setup['file'], None, None, is_module)
  File "/home/python/.pycharm_helpers/pydev/pydevd.py", line 1026, in run
    pydev_imports.execfile(file, globals, locals)  # execute the script
  File "/home/python/.pycharm_helpers/pydev/_pydev_imps/_pydev_execfile.py", line 18, in execfile
    exec(compile(contents+"\n", file, 'exec'), glob, loc)
  File "/home/python/Desktop/company_project/server/connect/connect_svr.py", line 455, in <module>
    g_obj_loop.run_forever()
  File "/usr/lib/python3.5/asyncio/base_events.py", line 345, in run_forever
    self._run_once()
  File "/usr/lib/python3.5/asyncio/base_events.py", line 1304, in _run_once
    handle._run()
  File "/usr/lib/python3.5/asyncio/events.py", line 125, in _run
    self._callback(*self._args)
  File "/usr/lib/python3.5/asyncio/tasks.py", line 307, in _wakeup
    self._step()
  File "/usr/lib/python3.5/asyncio/tasks.py", line 239, in _step
    result = coro.send(None)
  File "/home/python/Desktop/company_project/server/connect/connect_svr.py", line 373, in init
    yield from __initUpdate()
  File "/usr/lib/python3.5/asyncio/coroutines.py", line 206, in coro
    res = func(*args, **kw)
  File "/home/python/Desktop/company_project/server/connect/connect_svr.py", line 322, in __initUpdate
    asyncio.ensure_future(reciveMgr.classReciveMgr.getInstance().updatePushData(procVariable.host,procVariable.group_id))
task: <Task pending coro=<classReciveMgr.updatePushData() running at /home/python/Desktop/company_project/server/lib/reciveMgr.py:68> wait_for=<Future pending cb=[Task._wakeup()] created at /usr/lib/python3.5/asyncio/base_events.py:252> cb=[gather.<locals>._done_callback(7)() at /usr/lib/python3.5/asyncio/tasks.py:637] created at /home/python/Desktop/company_project/server/connect/connect_svr.py:322>
