2018-05-06 19:05:15,485|ERROR|fifoMgr.py:110|updateFifoChannel|CancelledError()
2018-05-06 19:05:49,692|ERROR|fifoMgr.py:110|updateFifoChannel|CancelledError()
2018-05-06 19:07:58,465|ERROR|fifoMgr.py:110|updateFifoChannel|CancelledError()
2018-05-06 19:21:41,456|ERROR|base_events.py:1260|default_exception_handler|_GatheringFuture exception was never retrieved
future: <_GatheringFuture finished exception=KeyboardInterrupt() created at /Library/Frameworks/Python.framework/Versions/3.6/lib/python3.6/asyncio/tasks.py:549>
source_traceback: Object created at (most recent call last):
  File "/Applications/PyCharm.app/Contents/helpers/pydev/pydevd.py", line 1664, in <module>
    main()
  File "/Applications/PyCharm.app/Contents/helpers/pydev/pydevd.py", line 1658, in main
    globals = debugger.run(setup['file'], None, None, is_module)
  File "/Applications/PyCharm.app/Contents/helpers/pydev/pydevd.py", line 1068, in run
    pydev_imports.execfile(file, globals, locals)  # execute the script
  File "/Applications/PyCharm.app/Contents/helpers/pydev/_pydev_imps/_pydev_execfile.py", line 18, in execfile
    exec(compile(contents+"\n", file, 'exec'), glob, loc)
  File "/Users/mac/server/logic/logic_svr.py", line 304, in <module>
    print(asyncio.gather(*asyncio.Task.all_tasks()).cancel())
  File "/Library/Frameworks/Python.framework/Versions/3.6/lib/python3.6/asyncio/tasks.py", line 612, in gather
    outer = _GatheringFuture(children, loop=loop)
  File "/Library/Frameworks/Python.framework/Versions/3.6/lib/python3.6/asyncio/tasks.py", line 549, in __init__
    super().__init__(loop=loop)
Traceback (most recent call last):
  File "/Users/mac/server/logic/logic_svr.py", line 301, in <module>
    g_obj_loop.run_forever()
  File "/Library/Frameworks/Python.framework/Versions/3.6/lib/python3.6/asyncio/base_events.py", line 421, in run_forever
    self._run_once()
  File "/Library/Frameworks/Python.framework/Versions/3.6/lib/python3.6/asyncio/base_events.py", line 1418, in _run_once
    handle._run()
  File "/Library/Frameworks/Python.framework/Versions/3.6/lib/python3.6/asyncio/events.py", line 127, in _run
    self._callback(*self._args)
  File "/Users/mac/server/lib/fifoMgr.py", line 109, in updateFifoChannel
    yield from asyncio.sleep(0.1)
  File "/Library/Frameworks/Python.framework/Versions/3.6/lib/python3.6/asyncio/tasks.py", line 477, in sleep
    future = loop.create_future()
  File "/Library/Frameworks/Python.framework/Versions/3.6/lib/python3.6/asyncio/base_events.py", line 275, in create_future
    return futures.Future(loop=self)
  File "/Library/Frameworks/Python.framework/Versions/3.6/lib/python3.6/traceback.py", line 205, in extract_stack
    if f is None:
KeyboardInterrupt
2018-05-06 19:22:24,990|WARNING|base_events.py:1422|_run_once|Executing <Task pending coro=<classFIFOMgr.updateFifoChannel() running at /Users/mac/server/lib/fifoMgr.py:95> wait_for=<Future pending cb=[<TaskWakeupMethWrapper object at 0x103a51a08>()] created at /Library/Frameworks/Python.framework/Versions/3.6/lib/python3.6/asyncio/base_events.py:275> created at /Users/mac/server/logic/logic_svr.py:167> took 4.012 seconds
2018-05-06 19:26:46,043|ERROR|fifoMgr.py:113|updateFifoChannel|CancelledError()
2018-05-06 19:45:31,417|ERROR|logic_svr.py:313|<module>|Traceback (most recent call last):
  File "/Users/mac/server/logic/logic_svr.py", line 206, in init
    yield from __initData()
  File "/Users/mac/server/logic/logic_svr.py", line 108, in __initData
    singletonDefine.g_obj_logicDataMgr = dataBaseMgr.classLogicDataBaseMgr(logic_config.redis_config_debug,
AttributeError: module 'datawrapper.dataBaseMgr' has no attribute 'classLogicDataBaseMgr'

During handling of the above exception, another exception occurred:

Traceback (most recent call last):
  File "/Users/mac/server/logic/logic_svr.py", line 303, in <module>
    g_obj_loop.run_forever()
  File "/Library/Frameworks/Python.framework/Versions/3.6/lib/python3.6/asyncio/base_events.py", line 421, in run_forever
    self._run_once()
  File "/Library/Frameworks/Python.framework/Versions/3.6/lib/python3.6/asyncio/base_events.py", line 1418, in _run_once
    handle._run()
  File "/Library/Frameworks/Python.framework/Versions/3.6/lib/python3.6/asyncio/events.py", line 127, in _run
    self._callback(*self._args)
  File "/Users/mac/server/logic/logic_svr.py", line 221, in init
    exit(0)
  File "/Library/Frameworks/Python.framework/Versions/3.6/lib/python3.6/_sitebuiltins.py", line 26, in __call__
    raise SystemExit(code)
SystemExit: 0

2018-05-06 19:45:31,423|ERROR|base_events.py:1260|default_exception_handler|Task was destroyed but it is pending!
source_traceback: Object created at (most recent call last):
  File "/Applications/PyCharm.app/Contents/helpers/pydev/pydevd.py", line 1664, in <module>
    main()
  File "/Applications/PyCharm.app/Contents/helpers/pydev/pydevd.py", line 1658, in main
    globals = debugger.run(setup['file'], None, None, is_module)
  File "/Applications/PyCharm.app/Contents/helpers/pydev/pydevd.py", line 1068, in run
    pydev_imports.execfile(file, globals, locals)  # execute the script
  File "/Applications/PyCharm.app/Contents/helpers/pydev/_pydev_imps/_pydev_execfile.py", line 18, in execfile
    exec(compile(contents+"\n", file, 'exec'), glob, loc)
  File "/Users/mac/server/logic/logic_svr.py", line 303, in <module>
    g_obj_loop.run_forever()
  File "/Library/Frameworks/Python.framework/Versions/3.6/lib/python3.6/asyncio/base_events.py", line 421, in run_forever
    self._run_once()
  File "/Library/Frameworks/Python.framework/Versions/3.6/lib/python3.6/asyncio/base_events.py", line 1418, in _run_once
    handle._run()
  File "/Library/Frameworks/Python.framework/Versions/3.6/lib/python3.6/asyncio/events.py", line 127, in _run
    self._callback(*self._args)
  File "/Users/mac/server/logic/logic_svr.py", line 204, in init
    yield from __initFiFo()
  File "/Users/mac/server/logic/logic_svr.py", line 102, in __initFiFo
    yield from fifoMgr.classFIFOMgr.getInstance().cleanFifoQueue()
  File "/Users/mac/server/lib/fifoMgr.py", line 49, in cleanFifoQueue
    yield from redis.delete(self.strCallName)
  File "/Library/Frameworks/Python.framework/Versions/3.6/lib/python3.6/site-packages/aioredis/pool.py", line 310, in __exit__
    self._pool.release(self._conn)
  File "/Library/Frameworks/Python.framework/Versions/3.6/lib/python3.6/site-packages/aioredis/pool.py", line 218, in release
    async_task(self._wakeup(), loop=self._loop)
task: <Task pending coro=<RedisPool._wakeup() running at /Library/Frameworks/Python.framework/Versions/3.6/lib/python3.6/site-packages/aioredis/pool.py:263> created at /Library/Frameworks/Python.framework/Versions/3.6/lib/python3.6/site-packages/aioredis/pool.py:218>
2018-05-06 19:45:31,444|ERROR|base_events.py:1260|default_exception_handler|Task exception was never retrieved
future: <Task finished coro=<init() done, defined at /Users/mac/server/logic/logic_svr.py:194> exception=SystemExit(0,)>
Traceback (most recent call last):
  File "/Users/mac/server/logic/logic_svr.py", line 206, in init
    yield from __initData()
  File "/Users/mac/server/logic/logic_svr.py", line 108, in __initData
    singletonDefine.g_obj_logicDataMgr = dataBaseMgr.classLogicDataBaseMgr(logic_config.redis_config_debug,
AttributeError: module 'datawrapper.dataBaseMgr' has no attribute 'classLogicDataBaseMgr'

During handling of the above exception, another exception occurred:

Traceback (most recent call last):
  File "/Users/mac/server/logic/logic_svr.py", line 303, in <module>
    g_obj_loop.run_forever()
  File "/Library/Frameworks/Python.framework/Versions/3.6/lib/python3.6/asyncio/base_events.py", line 421, in run_forever
    self._run_once()
  File "/Library/Frameworks/Python.framework/Versions/3.6/lib/python3.6/asyncio/base_events.py", line 1418, in _run_once
    handle._run()
  File "/Library/Frameworks/Python.framework/Versions/3.6/lib/python3.6/asyncio/events.py", line 127, in _run
    self._callback(*self._args)
  File "/Users/mac/server/logic/logic_svr.py", line 221, in init
    exit(0)
  File "/Library/Frameworks/Python.framework/Versions/3.6/lib/python3.6/_sitebuiltins.py", line 26, in __call__
    raise SystemExit(code)
SystemExit: 0
2018-05-06 19:45:31,463|ERROR|base_events.py:1260|default_exception_handler|Task was destroyed but it is pending!
source_traceback: Object created at (most recent call last):
  File "/Applications/PyCharm.app/Contents/helpers/pydev/pydevd.py", line 1664, in <module>
    main()
  File "/Applications/PyCharm.app/Contents/helpers/pydev/pydevd.py", line 1658, in main
    globals = debugger.run(setup['file'], None, None, is_module)
  File "/Applications/PyCharm.app/Contents/helpers/pydev/pydevd.py", line 1068, in run
    pydev_imports.execfile(file, globals, locals)  # execute the script
  File "/Applications/PyCharm.app/Contents/helpers/pydev/_pydev_imps/_pydev_execfile.py", line 18, in execfile
    exec(compile(contents+"\n", file, 'exec'), glob, loc)
  File "/Users/mac/server/logic/logic_svr.py", line 303, in <module>
    g_obj_loop.run_forever()
  File "/Library/Frameworks/Python.framework/Versions/3.6/lib/python3.6/asyncio/base_events.py", line 421, in run_forever
    self._run_once()
  File "/Library/Frameworks/Python.framework/Versions/3.6/lib/python3.6/asyncio/base_events.py", line 1426, in _run_once
    handle._run()
  File "/Library/Frameworks/Python.framework/Versions/3.6/lib/python3.6/asyncio/events.py", line 127, in _run
    self._callback(*self._args)
  File "/Users/mac/server/logic/logic_svr.py", line 204, in init
    yield from __initFiFo()
  File "/Users/mac/server/logic/logic_svr.py", line 95, in __initFiFo
    yield from fifoMgr.classFIFOMgr.getInstance().connectRedis()
  File "/Users/mac/server/lib/redismodule/redisMgr.py", line 59, in connectRedis
    password=self.strPwd,minsize=self.iMinPoolSize,maxsize=self.iMaxPoolSize,encoding=self.strEncodeing)
  File "/Library/Frameworks/Python.framework/Versions/3.6/lib/python3.6/site-packages/aioredis/pool.py", line 40, in create_pool
    ssl=ssl, loop=loop)
  File "/Library/Frameworks/Python.framework/Versions/3.6/lib/python3.6/site-packages/aioredis/pool.py", line 79, in __init__
    self._close_waiter = async_task(self._do_close(), loop=loop)
task: <Task pending coro=<RedisPool._do_close() running at /Library/Frameworks/Python.framework/Versions/3.6/lib/python3.6/site-packages/aioredis/pool.py:117> wait_for=<Future pending cb=[<TaskWakeupMethWrapper object at 0x104aac5e8>()] created at /Library/Frameworks/Python.framework/Versions/3.6/lib/python3.6/asyncio/base_events.py:275> created at /Library/Frameworks/Python.framework/Versions/3.6/lib/python3.6/site-packages/aioredis/pool.py:79>
2018-05-06 19:45:31,464|ERROR|base_events.py:1260|default_exception_handler|Task was destroyed but it is pending!
source_traceback: Object created at (most recent call last):
  File "/Applications/PyCharm.app/Contents/helpers/pydev/pydevd.py", line 1664, in <module>
    main()
  File "/Applications/PyCharm.app/Contents/helpers/pydev/pydevd.py", line 1658, in main
    globals = debugger.run(setup['file'], None, None, is_module)
  File "/Applications/PyCharm.app/Contents/helpers/pydev/pydevd.py", line 1068, in run
    pydev_imports.execfile(file, globals, locals)  # execute the script
  File "/Applications/PyCharm.app/Contents/helpers/pydev/_pydev_imps/_pydev_execfile.py", line 18, in execfile
    exec(compile(contents+"\n", file, 'exec'), glob, loc)
  File "/Users/mac/server/logic/logic_svr.py", line 303, in <module>
    g_obj_loop.run_forever()
  File "/Library/Frameworks/Python.framework/Versions/3.6/lib/python3.6/asyncio/base_events.py", line 421, in run_forever
    self._run_once()
  File "/Library/Frameworks/Python.framework/Versions/3.6/lib/python3.6/asyncio/base_events.py", line 1418, in _run_once
    handle._run()
  File "/Library/Frameworks/Python.framework/Versions/3.6/lib/python3.6/asyncio/events.py", line 127, in _run
    self._callback(*self._args)
  File "/Users/mac/server/logic/logic_svr.py", line 204, in init
    yield from __initFiFo()
  File "/Users/mac/server/logic/logic_svr.py", line 95, in __initFiFo
    yield from fifoMgr.classFIFOMgr.getInstance().connectRedis()
  File "/Users/mac/server/lib/redismodule/redisMgr.py", line 59, in connectRedis
    password=self.strPwd,minsize=self.iMinPoolSize,maxsize=self.iMaxPoolSize,encoding=self.strEncodeing)
  File "/Library/Frameworks/Python.framework/Versions/3.6/lib/python3.6/site-packages/aioredis/pool.py", line 42, in create_pool
    yield from pool._fill_free(override_min=False)
  File "/Library/Frameworks/Python.framework/Versions/3.6/lib/python3.6/site-packages/aioredis/pool.py", line 235, in _fill_free
    conn = yield from self._create_new_connection()
  File "/Library/Frameworks/Python.framework/Versions/3.6/lib/python3.6/site-packages/aioredis/commands/__init__.py", line 146, in create_redis
    loop=loop)
  File "/Library/Frameworks/Python.framework/Versions/3.6/lib/python3.6/site-packages/aioredis/connection.py", line 84, in create_connection
    address=address, loop=loop)
  File "/Library/Frameworks/Python.framework/Versions/3.6/lib/python3.6/site-packages/aioredis/connection.py", line 111, in __init__
    self._reader_task = async_task(self._read_data(), loop=self._loop)
task: <Task pending coro=<RedisConnection._read_data() running at /Library/Frameworks/Python.framework/Versions/3.6/lib/python3.6/site-packages/aioredis/connection.py:132> wait_for=<Future pending cb=[<TaskWakeupMethWrapper object at 0x104aac768>()] created at /Library/Frameworks/Python.framework/Versions/3.6/lib/python3.6/asyncio/base_events.py:275> cb=[Future.set_result()] created at /Library/Frameworks/Python.framework/Versions/3.6/lib/python3.6/site-packages/aioredis/connection.py:111>
2018-05-06 19:45:31,464|ERROR|base_events.py:1260|default_exception_handler|Task was destroyed but it is pending!
source_traceback: Object created at (most recent call last):
  File "/Applications/PyCharm.app/Contents/helpers/pydev/pydevd.py", line 1664, in <module>
    main()
  File "/Applications/PyCharm.app/Contents/helpers/pydev/pydevd.py", line 1658, in main
    globals = debugger.run(setup['file'], None, None, is_module)
  File "/Applications/PyCharm.app/Contents/helpers/pydev/pydevd.py", line 1068, in run
    pydev_imports.execfile(file, globals, locals)  # execute the script
  File "/Applications/PyCharm.app/Contents/helpers/pydev/_pydev_imps/_pydev_execfile.py", line 18, in execfile
    exec(compile(contents+"\n", file, 'exec'), glob, loc)
  File "/Users/mac/server/logic/logic_svr.py", line 303, in <module>
    g_obj_loop.run_forever()
  File "/Library/Frameworks/Python.framework/Versions/3.6/lib/python3.6/asyncio/base_events.py", line 421, in run_forever
    self._run_once()
  File "/Library/Frameworks/Python.framework/Versions/3.6/lib/python3.6/asyncio/base_events.py", line 1418, in _run_once
    handle._run()
  File "/Library/Frameworks/Python.framework/Versions/3.6/lib/python3.6/asyncio/events.py", line 127, in _run
    self._callback(*self._args)
  File "/Users/mac/server/logic/logic_svr.py", line 204, in init
    yield from __initFiFo()
  File "/Users/mac/server/logic/logic_svr.py", line 95, in __initFiFo
    yield from fifoMgr.classFIFOMgr.getInstance().connectRedis()
  File "/Users/mac/server/lib/redismodule/redisMgr.py", line 59, in connectRedis
    password=self.strPwd,minsize=self.iMinPoolSize,maxsize=self.iMaxPoolSize,encoding=self.strEncodeing)
  File "/Library/Frameworks/Python.framework/Versions/3.6/lib/python3.6/site-packages/aioredis/pool.py", line 42, in create_pool
    yield from pool._fill_free(override_min=False)
  File "/Library/Frameworks/Python.framework/Versions/3.6/lib/python3.6/site-packages/aioredis/pool.py", line 235, in _fill_free
    conn = yield from self._create_new_connection()
  File "/Library/Frameworks/Python.framework/Versions/3.6/lib/python3.6/site-packages/aioredis/commands/__init__.py", line 146, in create_redis
    loop=loop)
  File "/Library/Frameworks/Python.framework/Versions/3.6/lib/python3.6/site-packages/aioredis/connection.py", line 84, in create_connection
    address=address, loop=loop)
  File "/Library/Frameworks/Python.framework/Versions/3.6/lib/python3.6/site-packages/aioredis/connection.py", line 111, in __init__
    self._reader_task = async_task(self._read_data(), loop=self._loop)
task: <Task pending coro=<RedisConnection._read_data() running at /Library/Frameworks/Python.framework/Versions/3.6/lib/python3.6/site-packages/aioredis/connection.py:132> wait_for=<Future pending cb=[<TaskWakeupMethWrapper object at 0x103a0cfa8>()] created at /Library/Frameworks/Python.framework/Versions/3.6/lib/python3.6/asyncio/base_events.py:275> cb=[Future.set_result()] created at /Library/Frameworks/Python.framework/Versions/3.6/lib/python3.6/site-packages/aioredis/connection.py:111>
2018-05-06 19:46:50,381|WARNING|base_events.py:1422|_run_once|Executing <Handle <TaskWakeupMethWrapper object at 0x103afdb28>(<Future finis...events.py:275>) created at /Library/Frameworks/Python.framework/Versions/3.6/lib/python3.6/asyncio/tasks.py:390> took 0.105 seconds
2018-05-06 19:57:52,805|WARNING|base_events.py:1422|_run_once|Executing <TimerHandle when=243954.046898284 _set_result_unless_cancelled(<Future finis...events.py:275>, None) at /Library/Frameworks/Python.framework/Versions/3.6/lib/python3.6/asyncio/futures.py:344 created at /Library/Frameworks/Python.framework/Versions/3.6/lib/python3.6/asyncio/tasks.py:480> took 0.131 seconds
2018-05-06 22:21:19,775|ERROR|fifoMgr.py:113|updateFifoChannel|CancelledError()
