2018-06-20 19:24:47,508|ERROR|base_events.py:1148|default_exception_handler|Task exception was never retrieved
future: <Task finished coro=<init() done, defined at /home/python/Desktop/company_project/server/thirdweb/thirdweb_svr.py:181> exception=SystemExit(0,)>
Traceback (most recent call last):
  File "/usr/lib/python3.5/asyncio/base_events.py", line 958, in create_server
    sock.bind(sa)
OSError: [Errno 98] Address already in use

During handling of the above exception, another exception occurred:

Traceback (most recent call last):
  File "/home/python/Desktop/company_project/server/thirdweb/thirdweb_svr.py", line 195, in init
    yield from __initWebServer()
  File "/home/python/Desktop/company_project/server/thirdweb/thirdweb_svr.py", line 153, in __initWebServer
    yield from g_obj_loop.create_server(server, "0.0.0.0", 8083)
  File "/usr/lib/python3.5/asyncio/base_events.py", line 962, in create_server
    % (sa, err.strerror.lower()))
OSError: [Errno 98] error while attempting to bind on address ('0.0.0.0', 8083): address already in use

During handling of the above exception, another exception occurred:

Traceback (most recent call last):
  File "/home/python/Desktop/company_project/server/thirdweb/thirdweb_svr.py", line 242, in <module>
    g_obj_loop.run_forever()
  File "/usr/lib/python3.5/asyncio/base_events.py", line 345, in run_forever
    self._run_once()
  File "/usr/lib/python3.5/asyncio/base_events.py", line 1304, in _run_once
    handle._run()
  File "/usr/lib/python3.5/asyncio/events.py", line 125, in _run
    self._callback(*self._args)
  File "/usr/lib/python3.5/asyncio/tasks.py", line 307, in _wakeup
    self._step()
  File "/usr/lib/python3.5/asyncio/tasks.py", line 239, in _step
    result = coro.send(None)
  File "/home/python/Desktop/company_project/server/thirdweb/thirdweb_svr.py", line 203, in init
    exit(0)
  File "/usr/lib/python3.5/_sitebuiltins.py", line 26, in __call__
    raise SystemExit(code)
SystemExit: 0
2018-06-20 19:24:47,561|ERROR|base_events.py:1148|default_exception_handler|Task was destroyed but it is pending!
source_traceback: Object created at (most recent call last):
  File "/home/python/.pycharm_helpers/pydev/pydevd.py", line 1599, in <module>
    globals = debugger.run(setup['file'], None, None, is_module)
  File "/home/python/.pycharm_helpers/pydev/pydevd.py", line 1026, in run
    pydev_imports.execfile(file, globals, locals)  # execute the script
  File "/home/python/.pycharm_helpers/pydev/_pydev_imps/_pydev_execfile.py", line 18, in execfile
    exec(compile(contents+"\n", file, 'exec'), glob, loc)
  File "/home/python/Desktop/company_project/server/thirdweb/thirdweb_svr.py", line 242, in <module>
    g_obj_loop.run_forever()
  File "/usr/lib/python3.5/asyncio/base_events.py", line 345, in run_forever
    self._run_once()
  File "/usr/lib/python3.5/asyncio/base_events.py", line 1312, in _run_once
    handle._run()
  File "/usr/lib/python3.5/asyncio/events.py", line 125, in _run
    self._callback(*self._args)
  File "/usr/lib/python3.5/asyncio/tasks.py", line 239, in _step
    result = coro.send(None)
  File "/home/python/Desktop/company_project/server/thirdweb/thirdweb_svr.py", line 194, in init
    yield from __initLogicDataMgr()
  File "/home/python/Desktop/company_project/server/thirdweb/thirdweb_svr.py", line 135, in __initLogicDataMgr
    yield from classDataBaseMgr.getInstance().connectRedis()
  File "/home/python/Desktop/company_project/server/datawrapper/dataBaseMgr.py", line 91, in connectRedis
    yield from var_aio_obj.connectRedis()
  File "/home/python/Desktop/company_project/server/lib/redismodule/redisMgr.py", line 59, in connectRedis
    password=self.strPwd,minsize=self.iMinPoolSize,maxsize=self.iMaxPoolSize,encoding=self.strEncodeing)
  File "/usr/local/lib/python3.5/dist-packages/aioredis/pool.py", line 40, in create_pool
    ssl=ssl, loop=loop)
  File "/usr/local/lib/python3.5/dist-packages/aioredis/pool.py", line 79, in __init__
    self._close_waiter = async_task(self._do_close(), loop=loop)
task: <Task pending coro=<RedisPool._do_close() running at /usr/local/lib/python3.5/dist-packages/aioredis/pool.py:117> wait_for=<Future pending cb=[Task._wakeup()] created at /usr/lib/python3.5/asyncio/base_events.py:252> created at /usr/local/lib/python3.5/dist-packages/aioredis/pool.py:79>
2018-06-20 19:24:47,565|ERROR|base_events.py:1148|default_exception_handler|Task was destroyed but it is pending!
source_traceback: Object created at (most recent call last):
  File "/home/python/.pycharm_helpers/pydev/pydevd.py", line 1599, in <module>
    globals = debugger.run(setup['file'], None, None, is_module)
  File "/home/python/.pycharm_helpers/pydev/pydevd.py", line 1026, in run
    pydev_imports.execfile(file, globals, locals)  # execute the script
  File "/home/python/.pycharm_helpers/pydev/_pydev_imps/_pydev_execfile.py", line 18, in execfile
    exec(compile(contents+"\n", file, 'exec'), glob, loc)
  File "/home/python/Desktop/company_project/server/thirdweb/thirdweb_svr.py", line 242, in <module>
    g_obj_loop.run_forever()
  File "/usr/lib/python3.5/asyncio/base_events.py", line 345, in run_forever
    self._run_once()
  File "/usr/lib/python3.5/asyncio/base_events.py", line 1304, in _run_once
    handle._run()
  File "/usr/lib/python3.5/asyncio/events.py", line 125, in _run
    self._callback(*self._args)
  File "/usr/lib/python3.5/asyncio/tasks.py", line 307, in _wakeup
    self._step()
  File "/usr/lib/python3.5/asyncio/tasks.py", line 239, in _step
    result = coro.send(None)
  File "/home/python/Desktop/company_project/server/thirdweb/thirdweb_svr.py", line 194, in init
    yield from __initLogicDataMgr()
  File "/home/python/Desktop/company_project/server/thirdweb/thirdweb_svr.py", line 135, in __initLogicDataMgr
    yield from classDataBaseMgr.getInstance().connectRedis()
  File "/home/python/Desktop/company_project/server/datawrapper/dataBaseMgr.py", line 91, in connectRedis
    yield from var_aio_obj.connectRedis()
  File "/home/python/Desktop/company_project/server/lib/redismodule/redisMgr.py", line 59, in connectRedis
    password=self.strPwd,minsize=self.iMinPoolSize,maxsize=self.iMaxPoolSize,encoding=self.strEncodeing)
  File "/usr/local/lib/python3.5/dist-packages/aioredis/pool.py", line 40, in create_pool
    ssl=ssl, loop=loop)
  File "/usr/local/lib/python3.5/dist-packages/aioredis/pool.py", line 79, in __init__
    self._close_waiter = async_task(self._do_close(), loop=loop)
task: <Task pending coro=<RedisPool._do_close() running at /usr/local/lib/python3.5/dist-packages/aioredis/pool.py:117> wait_for=<Future pending cb=[Task._wakeup()] created at /usr/lib/python3.5/asyncio/base_events.py:252> created at /usr/local/lib/python3.5/dist-packages/aioredis/pool.py:79>
2018-06-20 19:24:47,567|ERROR|base_events.py:1148|default_exception_handler|Task was destroyed but it is pending!
source_traceback: Object created at (most recent call last):
  File "/home/python/.pycharm_helpers/pydev/pydevd.py", line 1599, in <module>
    globals = debugger.run(setup['file'], None, None, is_module)
  File "/home/python/.pycharm_helpers/pydev/pydevd.py", line 1026, in run
    pydev_imports.execfile(file, globals, locals)  # execute the script
  File "/home/python/.pycharm_helpers/pydev/_pydev_imps/_pydev_execfile.py", line 18, in execfile
    exec(compile(contents+"\n", file, 'exec'), glob, loc)
  File "/home/python/Desktop/company_project/server/thirdweb/thirdweb_svr.py", line 242, in <module>
    g_obj_loop.run_forever()
  File "/usr/lib/python3.5/asyncio/base_events.py", line 345, in run_forever
    self._run_once()
  File "/usr/lib/python3.5/asyncio/base_events.py", line 1304, in _run_once
    handle._run()
  File "/usr/lib/python3.5/asyncio/events.py", line 125, in _run
    self._callback(*self._args)
  File "/usr/lib/python3.5/asyncio/tasks.py", line 307, in _wakeup
    self._step()
  File "/usr/lib/python3.5/asyncio/tasks.py", line 239, in _step
    result = coro.send(None)
  File "/home/python/Desktop/company_project/server/thirdweb/thirdweb_svr.py", line 194, in init
    yield from __initLogicDataMgr()
  File "/home/python/Desktop/company_project/server/thirdweb/thirdweb_svr.py", line 135, in __initLogicDataMgr
    yield from classDataBaseMgr.getInstance().connectRedis()
  File "/home/python/Desktop/company_project/server/datawrapper/dataBaseMgr.py", line 91, in connectRedis
    yield from var_aio_obj.connectRedis()
  File "/home/python/Desktop/company_project/server/lib/redismodule/redisMgr.py", line 59, in connectRedis
    password=self.strPwd,minsize=self.iMinPoolSize,maxsize=self.iMaxPoolSize,encoding=self.strEncodeing)
  File "/usr/local/lib/python3.5/dist-packages/aioredis/pool.py", line 40, in create_pool
    ssl=ssl, loop=loop)
  File "/usr/local/lib/python3.5/dist-packages/aioredis/pool.py", line 79, in __init__
    self._close_waiter = async_task(self._do_close(), loop=loop)
task: <Task pending coro=<RedisPool._do_close() running at /usr/local/lib/python3.5/dist-packages/aioredis/pool.py:117> wait_for=<Future pending cb=[Task._wakeup()] created at /usr/lib/python3.5/asyncio/base_events.py:252> created at /usr/local/lib/python3.5/dist-packages/aioredis/pool.py:79>
2018-06-20 19:24:47,569|ERROR|base_events.py:1148|default_exception_handler|Task was destroyed but it is pending!
source_traceback: Object created at (most recent call last):
  File "/home/python/.pycharm_helpers/pydev/pydevd.py", line 1599, in <module>
    globals = debugger.run(setup['file'], None, None, is_module)
  File "/home/python/.pycharm_helpers/pydev/pydevd.py", line 1026, in run
    pydev_imports.execfile(file, globals, locals)  # execute the script
  File "/home/python/.pycharm_helpers/pydev/_pydev_imps/_pydev_execfile.py", line 18, in execfile
    exec(compile(contents+"\n", file, 'exec'), glob, loc)
  File "/home/python/Desktop/company_project/server/thirdweb/thirdweb_svr.py", line 242, in <module>
    g_obj_loop.run_forever()
  File "/usr/lib/python3.5/asyncio/base_events.py", line 345, in run_forever
    self._run_once()
  File "/usr/lib/python3.5/asyncio/base_events.py", line 1304, in _run_once
    handle._run()
  File "/usr/lib/python3.5/asyncio/events.py", line 125, in _run
    self._callback(*self._args)
  File "/usr/lib/python3.5/asyncio/tasks.py", line 307, in _wakeup
    self._step()
  File "/usr/lib/python3.5/asyncio/tasks.py", line 239, in _step
    result = coro.send(None)
  File "/home/python/Desktop/company_project/server/thirdweb/thirdweb_svr.py", line 194, in init
    yield from __initLogicDataMgr()
  File "/home/python/Desktop/company_project/server/thirdweb/thirdweb_svr.py", line 135, in __initLogicDataMgr
    yield from classDataBaseMgr.getInstance().connectRedis()
  File "/home/python/Desktop/company_project/server/datawrapper/dataBaseMgr.py", line 91, in connectRedis
    yield from var_aio_obj.connectRedis()
  File "/home/python/Desktop/company_project/server/lib/redismodule/redisMgr.py", line 59, in connectRedis
    password=self.strPwd,minsize=self.iMinPoolSize,maxsize=self.iMaxPoolSize,encoding=self.strEncodeing)
  File "/usr/local/lib/python3.5/dist-packages/aioredis/pool.py", line 42, in create_pool
    yield from pool._fill_free(override_min=False)
  File "/usr/local/lib/python3.5/dist-packages/aioredis/pool.py", line 235, in _fill_free
    conn = yield from self._create_new_connection()
  File "/usr/local/lib/python3.5/dist-packages/aioredis/commands/__init__.py", line 146, in create_redis
    loop=loop)
  File "/usr/local/lib/python3.5/dist-packages/aioredis/connection.py", line 84, in create_connection
    address=address, loop=loop)
  File "/usr/local/lib/python3.5/dist-packages/aioredis/connection.py", line 111, in __init__
    self._reader_task = async_task(self._read_data(), loop=self._loop)
task: <Task pending coro=<RedisConnection._read_data() running at /usr/local/lib/python3.5/dist-packages/aioredis/connection.py:132> wait_for=<Future pending cb=[Task._wakeup()] created at /usr/lib/python3.5/asyncio/base_events.py:252> cb=[Future.set_result()] created at /usr/local/lib/python3.5/dist-packages/aioredis/connection.py:111>
2018-06-20 19:24:47,570|ERROR|base_events.py:1148|default_exception_handler|Task was destroyed but it is pending!
source_traceback: Object created at (most recent call last):
  File "/home/python/.pycharm_helpers/pydev/pydevd.py", line 1599, in <module>
    globals = debugger.run(setup['file'], None, None, is_module)
  File "/home/python/.pycharm_helpers/pydev/pydevd.py", line 1026, in run
    pydev_imports.execfile(file, globals, locals)  # execute the script
  File "/home/python/.pycharm_helpers/pydev/_pydev_imps/_pydev_execfile.py", line 18, in execfile
    exec(compile(contents+"\n", file, 'exec'), glob, loc)
  File "/home/python/Desktop/company_project/server/thirdweb/thirdweb_svr.py", line 242, in <module>
    g_obj_loop.run_forever()
  File "/usr/lib/python3.5/asyncio/base_events.py", line 345, in run_forever
    self._run_once()
  File "/usr/lib/python3.5/asyncio/base_events.py", line 1304, in _run_once
    handle._run()
  File "/usr/lib/python3.5/asyncio/events.py", line 125, in _run
    self._callback(*self._args)
  File "/usr/lib/python3.5/asyncio/tasks.py", line 307, in _wakeup
    self._step()
  File "/usr/lib/python3.5/asyncio/tasks.py", line 239, in _step
    result = coro.send(None)
  File "/home/python/Desktop/company_project/server/thirdweb/thirdweb_svr.py", line 194, in init
    yield from __initLogicDataMgr()
  File "/home/python/Desktop/company_project/server/thirdweb/thirdweb_svr.py", line 135, in __initLogicDataMgr
    yield from classDataBaseMgr.getInstance().connectRedis()
  File "/home/python/Desktop/company_project/server/datawrapper/dataBaseMgr.py", line 91, in connectRedis
    yield from var_aio_obj.connectRedis()
  File "/home/python/Desktop/company_project/server/lib/redismodule/redisMgr.py", line 59, in connectRedis
    password=self.strPwd,minsize=self.iMinPoolSize,maxsize=self.iMaxPoolSize,encoding=self.strEncodeing)
  File "/usr/local/lib/python3.5/dist-packages/aioredis/pool.py", line 42, in create_pool
    yield from pool._fill_free(override_min=False)
  File "/usr/local/lib/python3.5/dist-packages/aioredis/pool.py", line 235, in _fill_free
    conn = yield from self._create_new_connection()
  File "/usr/local/lib/python3.5/dist-packages/aioredis/commands/__init__.py", line 146, in create_redis
    loop=loop)
  File "/usr/local/lib/python3.5/dist-packages/aioredis/connection.py", line 84, in create_connection
    address=address, loop=loop)
  File "/usr/local/lib/python3.5/dist-packages/aioredis/connection.py", line 111, in __init__
    self._reader_task = async_task(self._read_data(), loop=self._loop)
task: <Task pending coro=<RedisConnection._read_data() running at /usr/local/lib/python3.5/dist-packages/aioredis/connection.py:132> wait_for=<Future pending cb=[Task._wakeup()] created at /usr/lib/python3.5/asyncio/base_events.py:252> cb=[Future.set_result()] created at /usr/local/lib/python3.5/dist-packages/aioredis/connection.py:111>
2018-06-20 19:24:47,571|ERROR|base_events.py:1148|default_exception_handler|Task was destroyed but it is pending!
source_traceback: Object created at (most recent call last):
  File "/home/python/.pycharm_helpers/pydev/pydevd.py", line 1599, in <module>
    globals = debugger.run(setup['file'], None, None, is_module)
  File "/home/python/.pycharm_helpers/pydev/pydevd.py", line 1026, in run
    pydev_imports.execfile(file, globals, locals)  # execute the script
  File "/home/python/.pycharm_helpers/pydev/_pydev_imps/_pydev_execfile.py", line 18, in execfile
    exec(compile(contents+"\n", file, 'exec'), glob, loc)
  File "/home/python/Desktop/company_project/server/thirdweb/thirdweb_svr.py", line 242, in <module>
    g_obj_loop.run_forever()
  File "/usr/lib/python3.5/asyncio/base_events.py", line 345, in run_forever
    self._run_once()
  File "/usr/lib/python3.5/asyncio/base_events.py", line 1304, in _run_once
    handle._run()
  File "/usr/lib/python3.5/asyncio/events.py", line 125, in _run
    self._callback(*self._args)
  File "/usr/lib/python3.5/asyncio/tasks.py", line 307, in _wakeup
    self._step()
  File "/usr/lib/python3.5/asyncio/tasks.py", line 239, in _step
    result = coro.send(None)
  File "/home/python/Desktop/company_project/server/thirdweb/thirdweb_svr.py", line 194, in init
    yield from __initLogicDataMgr()
  File "/home/python/Desktop/company_project/server/thirdweb/thirdweb_svr.py", line 135, in __initLogicDataMgr
    yield from classDataBaseMgr.getInstance().connectRedis()
  File "/home/python/Desktop/company_project/server/datawrapper/dataBaseMgr.py", line 91, in connectRedis
    yield from var_aio_obj.connectRedis()
  File "/home/python/Desktop/company_project/server/lib/redismodule/redisMgr.py", line 59, in connectRedis
    password=self.strPwd,minsize=self.iMinPoolSize,maxsize=self.iMaxPoolSize,encoding=self.strEncodeing)
  File "/usr/local/lib/python3.5/dist-packages/aioredis/pool.py", line 42, in create_pool
    yield from pool._fill_free(override_min=False)
  File "/usr/local/lib/python3.5/dist-packages/aioredis/pool.py", line 235, in _fill_free
    conn = yield from self._create_new_connection()
  File "/usr/local/lib/python3.5/dist-packages/aioredis/commands/__init__.py", line 146, in create_redis
    loop=loop)
  File "/usr/local/lib/python3.5/dist-packages/aioredis/connection.py", line 84, in create_connection
    address=address, loop=loop)
  File "/usr/local/lib/python3.5/dist-packages/aioredis/connection.py", line 111, in __init__
    self._reader_task = async_task(self._read_data(), loop=self._loop)
task: <Task pending coro=<RedisConnection._read_data() running at /usr/local/lib/python3.5/dist-packages/aioredis/connection.py:132> wait_for=<Future pending cb=[Task._wakeup()] created at /usr/lib/python3.5/asyncio/base_events.py:252> cb=[Future.set_result()] created at /usr/local/lib/python3.5/dist-packages/aioredis/connection.py:111>
